<?xml version="1.0"?>
<robot name="c1_robot">

  <material name="dark_gray"><color rgba="0.25 0.25 0.25 1.0"/></material>
  <material name="black"><color rgba="0.05 0.05 0.05 1.0"/></material>
  <material name="light_gray"><color rgba="0.75 0.75 0.75 1.0"/></material>
  <material name="aluminum"><color rgba="0.6 0.63 0.65 1.0"/></material>
  <material name="navy"><color rgba="0.08 0.08 0.2 1.0"/></material>
  <material name="red"><color rgba="0.7 0.1 0.1 1.0"/></material>
  <material name="orange"><color rgba="0.9 0.5 0.1 1.0"/></material>
  <material name="yellow"><color rgba="1.0 0.85 0.0 1.0"/></material>

  <!-- ========== BASE ========== -->
  <link name="base_link">
    <visual>
      <origin xyz="0 0 0.059" rpy="0 0 0"/>
      <geometry><box size="0.40 0.23 0.02"/></geometry>
      <material name="dark_gray"/>
    </visual>
    <visual>
      <origin xyz="0 0 0.059" rpy="0 0 0"/>
      <geometry><box size="0.12 0.35 0.02"/></geometry>
      <material name="dark_gray"/>
    </visual>
    <collision>
      <origin xyz="0 0 0.059" rpy="0 0 0"/>
      <geometry><box size="0.40 0.35 0.02"/></geometry>
    </collision>
    <inertial>
      <mass value="5.0"/><origin xyz="0 0 0.059"/>
      <inertia ixx="0.03" ixy="0" ixz="0" iyy="0.05" iyz="0" izz="0.06"/>
    </inertial>
  </link>

  <!-- ========== MECANUM WHEELS ========== -->

  <!-- front_left_wheel -->
  <link name="front_left_wheel">
    <visual>
      <origin xyz="0 0 0" rpy="1.5708 0 0"/>
      <geometry><cylinder radius="0.022" length="0.052"/></geometry>
      <material name="black"/>
    </visual>
    <visual>
      <origin xyz="0 0.024 0" rpy="1.5708 0 0"/>
      <geometry><cylinder radius="0.035" length="0.004"/></geometry>
      <material name="dark_gray"/>
    </visual>
    <visual>
      <origin xyz="0 -0.024 0" rpy="1.5708 0 0"/>
      <geometry><cylinder radius="0.035" length="0.004"/></geometry>
      <material name="dark_gray"/>
    </visual>
    <visual>
      <origin xyz="0.0000 0 0.0380" rpy="0 1.5708 2.3562"/>
      <geometry>
        <cylinder radius="0.011" length="0.048"/>
      </geometry>
      <material name="roller_color"><color rgba="0.0 1.0 0.3 1.0"/></material>
    </visual>
    <visual>
      <origin xyz="0.0269 0 0.0269" rpy="0 1.0472 2.1863"/>
      <geometry>
        <cylinder radius="0.011" length="0.048"/>
      </geometry>
      <material name="roller_color"><color rgba="0.0 1.0 0.3 1.0"/></material>
    </visual>
    <visual>
      <origin xyz="0.0380 0 0.0000" rpy="0 0.7854 1.5708"/>
      <geometry>
        <cylinder radius="0.011" length="0.048"/>
      </geometry>
      <material name="roller_color"><color rgba="0.0 1.0 0.3 1.0"/></material>
    </visual>
    <visual>
      <origin xyz="0.0269 0 -0.0269" rpy="0 1.0472 0.9553"/>
      <geometry>
        <cylinder radius="0.011" length="0.048"/>
      </geometry>
      <material name="roller_color"><color rgba="0.0 1.0 0.3 1.0"/></material>
    </visual>
    <visual>
      <origin xyz="0.0000 0 -0.0380" rpy="0 1.5708 0.7854"/>
      <geometry>
        <cylinder radius="0.011" length="0.048"/>
      </geometry>
      <material name="roller_color"><color rgba="0.0 1.0 0.3 1.0"/></material>
    </visual>
    <visual>
      <origin xyz="-0.0269 0 -0.0269" rpy="0 2.0944 0.9553"/>
      <geometry>
        <cylinder radius="0.011" length="0.048"/>
      </geometry>
      <material name="roller_color"><color rgba="0.0 1.0 0.3 1.0"/></material>
    </visual>
    <visual>
      <origin xyz="-0.0380 0 -0.0000" rpy="0 2.3562 1.5708"/>
      <geometry>
        <cylinder radius="0.011" length="0.048"/>
      </geometry>
      <material name="roller_color"><color rgba="0.0 1.0 0.3 1.0"/></material>
    </visual>
    <visual>
      <origin xyz="-0.0269 0 0.0269" rpy="0 2.0944 2.1863"/>
      <geometry>
        <cylinder radius="0.011" length="0.048"/>
      </geometry>
      <material name="roller_color"><color rgba="0.0 1.0 0.3 1.0"/></material>
    </visual>
    <collision>
      <origin xyz="0 0 0" rpy="1.5708 0 0"/>
      <geometry><cylinder radius="0.049" length="0.05"/></geometry>
    </collision>
    <inertial>
      <mass value="0.5"/>
      <origin xyz="0 0 0"/>
      <inertia ixx="0.0004" ixy="0" ixz="0" iyy="0.0004" iyz="0" izz="0.0006"/>
    </inertial>
  </link>
  <joint name="front_left_wheel_joint" type="continuous">
    <parent link="base_link"/>
    <child link="front_left_wheel"/>
    <origin xyz="0.1100 0.1500 0.049" rpy="0 0 0"/>
    <axis xyz="0 1 0"/>
  </joint>

  <!-- front_right_wheel -->
  <link name="front_right_wheel">
    <visual>
      <origin xyz="0 0 0" rpy="1.5708 0 0"/>
      <geometry><cylinder radius="0.022" length="0.052"/></geometry>
      <material name="black"/>
    </visual>
    <visual>
      <origin xyz="0 0.024 0" rpy="1.5708 0 0"/>
      <geometry><cylinder radius="0.035" length="0.004"/></geometry>
      <material name="dark_gray"/>
    </visual>
    <visual>
      <origin xyz="0 -0.024 0" rpy="1.5708 0 0"/>
      <geometry><cylinder radius="0.035" length="0.004"/></geometry>
      <material name="dark_gray"/>
    </visual>
    <visual>
      <origin xyz="0.0000 0 0.0380" rpy="0 1.5708 -2.3562"/>
      <geometry>
        <cylinder radius="0.011" length="0.048"/>
      </geometry>
      <material name="roller_color"><color rgba="0.0 1.0 0.3 1.0"/></material>
    </visual>
    <visual>
      <origin xyz="0.0269 0 0.0269" rpy="0 1.0472 -2.1863"/>
      <geometry>
        <cylinder radius="0.011" length="0.048"/>
      </geometry>
      <material name="roller_color"><color rgba="0.0 1.0 0.3 1.0"/></material>
    </visual>
    <visual>
      <origin xyz="0.0380 0 0.0000" rpy="0 0.7854 -1.5708"/>
      <geometry>
        <cylinder radius="0.011" length="0.048"/>
      </geometry>
      <material name="roller_color"><color rgba="0.0 1.0 0.3 1.0"/></material>
    </visual>
    <visual>
      <origin xyz="0.0269 0 -0.0269" rpy="0 1.0472 -0.9553"/>
      <geometry>
        <cylinder radius="0.011" length="0.048"/>
      </geometry>
      <material name="roller_color"><color rgba="0.0 1.0 0.3 1.0"/></material>
    </visual>
    <visual>
      <origin xyz="0.0000 0 -0.0380" rpy="0 1.5708 -0.7854"/>
      <geometry>
        <cylinder radius="0.011" length="0.048"/>
      </geometry>
      <material name="roller_color"><color rgba="0.0 1.0 0.3 1.0"/></material>
    </visual>
    <visual>
      <origin xyz="-0.0269 0 -0.0269" rpy="0 2.0944 -0.9553"/>
      <geometry>
        <cylinder radius="0.011" length="0.048"/>
      </geometry>
      <material name="roller_color"><color rgba="0.0 1.0 0.3 1.0"/></material>
    </visual>
    <visual>
      <origin xyz="-0.0380 0 -0.0000" rpy="0 2.3562 -1.5708"/>
      <geometry>
        <cylinder radius="0.011" length="0.048"/>
      </geometry>
      <material name="roller_color"><color rgba="0.0 1.0 0.3 1.0"/></material>
    </visual>
    <visual>
      <origin xyz="-0.0269 0 0.0269" rpy="0 2.0944 -2.1863"/>
      <geometry>
        <cylinder radius="0.011" length="0.048"/>
      </geometry>
      <material name="roller_color"><color rgba="0.0 1.0 0.3 1.0"/></material>
    </visual>
    <collision>
      <origin xyz="0 0 0" rpy="1.5708 0 0"/>
      <geometry><cylinder radius="0.049" length="0.05"/></geometry>
    </collision>
    <inertial>
      <mass value="0.5"/>
      <origin xyz="0 0 0"/>
      <inertia ixx="0.0004" ixy="0" ixz="0" iyy="0.0004" iyz="0" izz="0.0006"/>
    </inertial>
  </link>
  <joint name="front_right_wheel_joint" type="continuous">
    <parent link="base_link"/>
    <child link="front_right_wheel"/>
    <origin xyz="0.1100 -0.1500 0.049" rpy="0 0 0"/>
    <axis xyz="0 1 0"/>
  </joint>

  <!-- rear_left_wheel -->
  <link name="rear_left_wheel">
    <visual>
      <origin xyz="0 0 0" rpy="1.5708 0 0"/>
      <geometry><cylinder radius="0.022" length="0.052"/></geometry>
      <material name="black"/>
    </visual>
    <visual>
      <origin xyz="0 0.024 0" rpy="1.5708 0 0"/>
      <geometry><cylinder radius="0.035" length="0.004"/></geometry>
      <material name="dark_gray"/>
    </visual>
    <visual>
      <origin xyz="0 -0.024 0" rpy="1.5708 0 0"/>
      <geometry><cylinder radius="0.035" length="0.004"/></geometry>
      <material name="dark_gray"/>
    </visual>
    <visual>
      <origin xyz="0.0000 0 0.0380" rpy="0 1.5708 -2.3562"/>
      <geometry>
        <cylinder radius="0.011" length="0.048"/>
      </geometry>
      <material name="roller_color"><color rgba="0.0 1.0 0.3 1.0"/></material>
    </visual>
    <visual>
      <origin xyz="0.0269 0 0.0269" rpy="0 1.0472 -2.1863"/>
      <geometry>
        <cylinder radius="0.011" length="0.048"/>
      </geometry>
      <material name="roller_color"><color rgba="0.0 1.0 0.3 1.0"/></material>
    </visual>
    <visual>
      <origin xyz="0.0380 0 0.0000" rpy="0 0.7854 -1.5708"/>
      <geometry>
        <cylinder radius="0.011" length="0.048"/>
      </geometry>
      <material name="roller_color"><color rgba="0.0 1.0 0.3 1.0"/></material>
    </visual>
    <visual>
      <origin xyz="0.0269 0 -0.0269" rpy="0 1.0472 -0.9553"/>
      <geometry>
        <cylinder radius="0.011" length="0.048"/>
      </geometry>
      <material name="roller_color"><color rgba="0.0 1.0 0.3 1.0"/></material>
    </visual>
    <visual>
      <origin xyz="0.0000 0 -0.0380" rpy="0 1.5708 -0.7854"/>
      <geometry>
        <cylinder radius="0.011" length="0.048"/>
      </geometry>
      <material name="roller_color"><color rgba="0.0 1.0 0.3 1.0"/></material>
    </visual>
    <visual>
      <origin xyz="-0.0269 0 -0.0269" rpy="0 2.0944 -0.9553"/>
      <geometry>
        <cylinder radius="0.011" length="0.048"/>
      </geometry>
      <material name="roller_color"><color rgba="0.0 1.0 0.3 1.0"/></material>
    </visual>
    <visual>
      <origin xyz="-0.0380 0 -0.0000" rpy="0 2.3562 -1.5708"/>
      <geometry>
        <cylinder radius="0.011" length="0.048"/>
      </geometry>
      <material name="roller_color"><color rgba="0.0 1.0 0.3 1.0"/></material>
    </visual>
    <visual>
      <origin xyz="-0.0269 0 0.0269" rpy="0 2.0944 -2.1863"/>
      <geometry>
        <cylinder radius="0.011" length="0.048"/>
      </geometry>
      <material name="roller_color"><color rgba="0.0 1.0 0.3 1.0"/></material>
    </visual>
    <collision>
      <origin xyz="0 0 0" rpy="1.5708 0 0"/>
      <geometry><cylinder radius="0.049" length="0.05"/></geometry>
    </collision>
    <inertial>
      <mass value="0.5"/>
      <origin xyz="0 0 0"/>
      <inertia ixx="0.0004" ixy="0" ixz="0" iyy="0.0004" iyz="0" izz="0.0006"/>
    </inertial>
  </link>
  <joint name="rear_left_wheel_joint" type="continuous">
    <parent link="base_link"/>
    <child link="rear_left_wheel"/>
    <origin xyz="-0.1100 0.1500 0.049" rpy="0 0 0"/>
    <axis xyz="0 1 0"/>
  </joint>

  <!-- rear_right_wheel -->
  <link name="rear_right_wheel">
    <visual>
      <origin xyz="0 0 0" rpy="1.5708 0 0"/>
      <geometry><cylinder radius="0.022" length="0.052"/></geometry>
      <material name="black"/>
    </visual>
    <visual>
      <origin xyz="0 0.024 0" rpy="1.5708 0 0"/>
      <geometry><cylinder radius="0.035" length="0.004"/></geometry>
      <material name="dark_gray"/>
    </visual>
    <visual>
      <origin xyz="0 -0.024 0" rpy="1.5708 0 0"/>
      <geometry><cylinder radius="0.035" length="0.004"/></geometry>
      <material name="dark_gray"/>
    </visual>
    <visual>
      <origin xyz="0.0000 0 0.0380" rpy="0 1.5708 2.3562"/>
      <geometry>
        <cylinder radius="0.011" length="0.048"/>
      </geometry>
      <material name="roller_color"><color rgba="0.0 1.0 0.3 1.0"/></material>
    </visual>
    <visual>
      <origin xyz="0.0269 0 0.0269" rpy="0 1.0472 2.1863"/>
      <geometry>
        <cylinder radius="0.011" length="0.048"/>
      </geometry>
      <material name="roller_color"><color rgba="0.0 1.0 0.3 1.0"/></material>
    </visual>
    <visual>
      <origin xyz="0.0380 0 0.0000" rpy="0 0.7854 1.5708"/>
      <geometry>
        <cylinder radius="0.011" length="0.048"/>
      </geometry>
      <material name="roller_color"><color rgba="0.0 1.0 0.3 1.0"/></material>
    </visual>
    <visual>
      <origin xyz="0.0269 0 -0.0269" rpy="0 1.0472 0.9553"/>
      <geometry>
        <cylinder radius="0.011" length="0.048"/>
      </geometry>
      <material name="roller_color"><color rgba="0.0 1.0 0.3 1.0"/></material>
    </visual>
    <visual>
      <origin xyz="0.0000 0 -0.0380" rpy="0 1.5708 0.7854"/>
      <geometry>
        <cylinder radius="0.011" length="0.048"/>
      </geometry>
      <material name="roller_color"><color rgba="0.0 1.0 0.3 1.0"/></material>
    </visual>
    <visual>
      <origin xyz="-0.0269 0 -0.0269" rpy="0 2.0944 0.9553"/>
      <geometry>
        <cylinder radius="0.011" length="0.048"/>
      </geometry>
      <material name="roller_color"><color rgba="0.0 1.0 0.3 1.0"/></material>
    </visual>
    <visual>
      <origin xyz="-0.0380 0 -0.0000" rpy="0 2.3562 1.5708"/>
      <geometry>
        <cylinder radius="0.011" length="0.048"/>
      </geometry>
      <material name="roller_color"><color rgba="0.0 1.0 0.3 1.0"/></material>
    </visual>
    <visual>
      <origin xyz="-0.0269 0 0.0269" rpy="0 2.0944 2.1863"/>
      <geometry>
        <cylinder radius="0.011" length="0.048"/>
      </geometry>
      <material name="roller_color"><color rgba="0.0 1.0 0.3 1.0"/></material>
    </visual>
    <collision>
      <origin xyz="0 0 0" rpy="1.5708 0 0"/>
      <geometry><cylinder radius="0.049" length="0.05"/></geometry>
    </collision>
    <inertial>
      <mass value="0.5"/>
      <origin xyz="0 0 0"/>
      <inertia ixx="0.0004" ixy="0" ixz="0" iyy="0.0004" iyz="0" izz="0.0006"/>
    </inertial>
  </link>
  <joint name="rear_right_wheel_joint" type="continuous">
    <parent link="base_link"/>
    <child link="rear_right_wheel"/>
    <origin xyz="-0.1100 -0.1500 0.049" rpy="0 0 0"/>
    <axis xyz="0 1 0"/>
  </joint>

  <!-- ========== LEVEL 2 LEGS ========== -->
  <link name="level2_leg_fl"><visual><geometry><cylinder radius="0.01" length="0.09"/></geometry><material name="aluminum"/></visual><inertial><mass value="0.1"/><inertia ixx="0.0001" ixy="0" ixz="0" iyy="0.0001" iyz="0" izz="0.0001"/></inertial></link>
  <joint name="level2_leg_fl_joint" type="fixed"><parent link="base_link"/><child link="level2_leg_fl"/><origin xyz="0.16 0.10 0.114"/></joint>

  <link name="level2_leg_fr"><visual><geometry><cylinder radius="0.01" length="0.09"/></geometry><material name="aluminum"/></visual><inertial><mass value="0.1"/><inertia ixx="0.0001" ixy="0" ixz="0" iyy="0.0001" iyz="0" izz="0.0001"/></inertial></link>
  <joint name="level2_leg_fr_joint" type="fixed"><parent link="base_link"/><child link="level2_leg_fr"/><origin xyz="0.16 -0.10 0.114"/></joint>

  <link name="level2_leg_rl"><visual><geometry><cylinder radius="0.01" length="0.09"/></geometry><material name="aluminum"/></visual><inertial><mass value="0.1"/><inertia ixx="0.0001" ixy="0" ixz="0" iyy="0.0001" iyz="0" izz="0.0001"/></inertial></link>
  <joint name="level2_leg_rl_joint" type="fixed"><parent link="base_link"/><child link="level2_leg_rl"/><origin xyz="-0.16 0.10 0.114"/></joint>

  <link name="level2_leg_rr"><visual><geometry><cylinder radius="0.01" length="0.09"/></geometry><material name="aluminum"/></visual><inertial><mass value="0.1"/><inertia ixx="0.0001" ixy="0" ixz="0" iyy="0.0001" iyz="0" izz="0.0001"/></inertial></link>
  <joint name="level2_leg_rr_joint" type="fixed"><parent link="base_link"/><child link="level2_leg_rr"/><origin xyz="-0.16 -0.10 0.114"/></joint>

  <!-- ========== LEVEL 2 PLATFORM ========== -->
  <link name="level2_platform">
    <visual><geometry><box size="0.38 0.25 0.01"/></geometry><material name="light_gray"/></visual>
    <collision><geometry><box size="0.38 0.25 0.01"/></geometry></collision>
    <inertial><mass value="1.0"/><inertia ixx="0.005" ixy="0" ixz="0" iyy="0.01" iyz="0" izz="0.015"/></inertial>
  </link>
  <joint name="level2_platform_joint" type="fixed"><parent link="base_link"/><child link="level2_platform"/><origin xyz="0 0 0.164"/></joint>

  <!-- ========== NUC ========== -->
  <link name="nuc">
    <visual><geometry><box size="0.12 0.124 0.05"/></geometry><material name="navy"/></visual>
    <collision><geometry><box size="0.12 0.124 0.05"/></geometry></collision>
    <inertial><mass value="1.2"/><inertia ixx="0.001" ixy="0" ixz="0" iyy="0.001" iyz="0" izz="0.001"/></inertial>
  </link>
  <joint name="nuc_joint" type="fixed"><parent link="level2_platform"/><child link="nuc"/><origin xyz="0.09 0 0.030"/></joint>

  <!-- ========== LIDAR ========== -->
  <link name="lidar_link">
    <visual><geometry><cylinder radius="0.035" length="0.04"/></geometry><material name="red"/></visual>
    <collision><geometry><cylinder radius="0.035" length="0.04"/></geometry></collision>
    <inertial><mass value="0.2"/><inertia ixx="0.0001" ixy="0" ixz="0" iyy="0.0001" iyz="0" izz="0.0001"/></inertial>
  </link>
  <joint name="lidar_joint" type="fixed"><parent link="nuc"/><child link="lidar_link"/><origin xyz="0 0 0.045"/></joint>

  <link name="laser_frame"/>
  <joint name="laser_frame_joint" type="fixed"><parent link="lidar_link"/><child link="laser_frame"/><origin xyz="0 0 0.02"/></joint>

</robot>
